## 예외처리(Exception handling)
### 프로그램 오류
소스코드를 컴파일하면 컴파일러가 소스코드(*.java)에 대해 오타나 잘못된 구문, 자료형 체크 등의 기본적인 검사를 수행하여 오류가 있는지를 알려 준다. 컴파일을 성공적으로 마치고 나면, 클래스 파일(*.class)이 생성되고, 생성된 클래스 파일을 실행할 수 있게 되는 것이다.   
   
- 에러(error) : 프로그램 코드에 의해서 수습될 수 없는 심각한 오류
- 예외(exception) : 프로그램 코드에 의해서 수습될 수 있는 다소 미약한 오류
   
### 예외 클래스의 계층구조
- Exception클래스들 : 사용자의 실수와 같은 외적인 요인에 의해 발생하는 예외
- RuntimeException클래스들 : 프로그래머의 실수로 발생하는 예외
   
### 예외처리하기 - try-catch문
발생한 예외를 처리하지 못하면, 프로그램은 비정상적으로 종료되며, 처리되지 못한 예외는 JVM의 '예외처리기(UncaughtExceptionHandler)'가 받아서 예외의 원인을 화면에 출력한다   
* 그러나 catch블럭 내에 또 하나의 try-catch문이 포함된 경우, 같은 이름의 참조변수를 사용해서는 안된다
   
### 예외 발생과 catch블럭
- printStackTrace() : 예외발생 당시의 호출스택에 있었던 메서드의 정보와 예외 메시지를 화면에 출력한다
- getMessage() : 발생한 예외클래스의 인스턴스에 저장된 메시지를 얻을 수 있다
- 멀티 catch블럭 : 여러 catch블럭을 '|'기호를 이용해서, 하나의 catch블럭으로 합칠 수 있다. 멀티 catch블럭 내에서는 실제로 어떤 예외가 발생한 것인지 알 수 없다. 그래서 참조변수 e로 멀티 catch블럭에 '|'기호로 연결된 예외 클래스들의 공통 분모인 조상 예외 클래스에 선언된 멤버만 사용할 수 있다.
   
### 예외 발생시키기
Exception인스턴스를 생성할 때, 생성자에 String을 넣어주면, 이 String이 Exception인스턴스에 메시지로 저장된다. 이 메시지는 getMessage()를 이용해서 얻을 수 있다.
* 컴파일러가 예외처리를 확인하지 않는 RuntimeException클래스들은 'unchecked예외'라고 부르고, 예외처리를 확인하는 Exception클래스들은 'checked예외'라고 부른다.
   
### 메서드에 예외 선언하기
메서드에 예외를 선언할 때 일반적으로 RuntimeException클래스들은 적지 않는다. 메서드의 throws에 명시하는 것은 예외를 처리하는 것이 아니라, 자신을 호출한 메서드에게 예외를 전달하여 예외처리를 떠맡기는 것이다.
   
### finally블럭
예외의 발생여부에 상관없이 실행되어야할 코드를 포함한다. try-catch문의 끝에 선택적으로 덧붙여 사용할 수 있다.
   
### 자동 자원 반환 - try-with-resources문
```
  try (FileInputStream fis = new FileInputStream("score.dat"));   
       DataInputStream dis = new DataInputStream(fis)) { ... }
```
try-with-resources문의 괄호() 안에 객체를 생성하는 문장을 넣으면, 이 객체는 따로 close()를 호출하지 않아도 try블럭을 벗어나는 순간 자동적으로 close()가 호출된다. 그 다음에 catch블럭 또는 finally블럭이 수행된다. try-with-resources문에 의해 자동으로 객체의 close()가 호출될 수 있으려면, 클래스가 AutoCloseable이라는 인터페이스를 구현한 것이어야만 한다.   
   
* Throwable에는 억제된 예외와 관련된 다음과 같은 메서드가 정의되어 있다
- void addSuppressed(Throwable exception) : 억제된 예외를 추가
- Throwable[] getSuppressed() : 억제된 예외(배열)를 반환
   
### 예외 되던지기(exception re-throwing)
예외가 발생할 가능성이 있는 메서드에서 try-catch문을 사용해서 예외를 처리해주고 catch문에서 필요한 작업을 행한 후에 throw문을 사용해서 예외를 다시 발생시킨다. 다시 발생한 예외는 이 메서드를 호출한 메서드에게 전달되고 호출한 메서드의 try-catch문에서 예외를 또다시 처리한다.   
이 방법은 하나의 예외에 대해서 예외가 발생한 메서드와 이를 호출한 메서드 양쪽 모두에서 처리해줘야 할 작업이 있을 때 사용된다. 이 때 주의할 점은 예외가 발생할 메서드에서는 선언부에 발생할 예외를 throws에 지정해줘야 한다는 것이다.
   
### 연결된 예외(chained exception)
```
  try {
    startInstall(); // SpaceException 발생
    copyFiles();
  } catch (SpaceException e) {
    InstallException ie = new InstallException("설치중 예외발생"); // 예외 생성
    ie.initCause(e);  // InstallException을 발생시킨다
    throw ie;
  } catch (MemoryException me) { ... }
```
   
- Throwable initCause(Throwable cause) : 지정한 예외를 원인 예외로 등록
- Throwable getCause() : 원인 예외를 반환
   
연결된 예외를 쓰는 이유는 여러가지 예외를 하나의 큰 분류의 예외로 묶어서 다루기 위해서이다. 두 예외는 상속관계가 아니어도 상관없다. 또 다른 이유는 checked예외를 unchecked예외로 바꿀 수 있도록 하기 위해서이다.
```
  static void startInstall() throws SpaceException {
    if(!enoughSpace())
      throw new SpaceException("설치할 공간이 부족합니다.");
    if(!enoughMemory())
      throw new RuntimeException(new MemoryException("메모리가 부족합니다."));
  }
```
위의 코드에서는 initCause() 대신 RuntimeException의 생성자를 사용했다.
- RuntimeException(Throwable cause) // 원인 예외를 등록하는 생성자

    
